<?xml version="1.0"?>
<robot name="small_robot${suffix}">
        
  <material name="red">
      <color rgba="1.0 0.0 0.0 1"/>
  </material>

  <material name="green_light">
      <color rgba="0.0 1.0 0.0 1"/>
  </material>

  <material name="green_dark">
    <color rgba="0.0 0.5 0.0 1"/>
  </material>

  <material name="blue">
      <color rgba="0.0 0.0 1.0 1"/>
  </material>

  <material name="yellow">
      <color rgba="1.0 1.0 0.0 1"/>
  </material>

  <material name="black">
      <color rgba="0.0 0.0 0.0 1"/>
  </material>

  <material name="white">
      <color rgba="1.0 1.0 1.0 1"/>
  </material>

  <!-- Base link -->
  <link name="base_link${suffix}">
    <inertial>
      <mass value="15.0"/>
      <origin rpy="0 0 0" xyz="0 0 0"/>
      <inertia ixx="1.628" ixy="0" ixz="0" iyy="1.628" iyz="0" izz="2.5"/>
    </inertial>
    <visual>
      <geometry>
        <box size="1.0 1.0 0.55"/>
        <material>Gazebo/Red</material>
        <!--<mesh filename="model://robot/files/robot.dae" scale="1.0 1.0 1.0"/> -->
      </geometry>
    </visual>
    <collision name="collision">
      <geometry>
        <box size="1.0 1.0 0.55"/>
        <!--<mesh filename="model://robot/files/robot.dae" scale="1.0 1.0 1.0"/> -->
      </geometry>
    </collision>

  </link>


  <!-- Wheel Left -->
  <link name="left_wheel${suffix}">      
    <visual>
      <origin rpy="-1.5707 0 0" xyz="0 0 0"/>
      <geometry>
        <cylinder length="0.2" radius="0.2"/>
        <!--<mesh filename="model://robot/files/wheel.dae" scale="1.0 1.0 1.0"/> -->
      </geometry>
      <material name="black"/>
    </visual>
    <collision>
      <origin rpy="-1.5707 0 0" xyz="0 0 0"/>
      <geometry>
        <cylinder length="0.2" radius="0.2"/>
        <!--<mesh filename="model://robot/files/wheel.dae" scale="1.0 1.0 1.0"/> -->
      </geometry>
    </collision>
    <inertial>
      <origin rpy="-1.5707 0 0" xyz="0 0 0"/>
      <mass value="4.0"/>
      <inertia ixx="0.05333" ixy="0" ixz="0" iyy="0.05333" iyz="0" izz="0.08"/>
    </inertial>
  </link>

  <gazebo reference="left_wheel${suffix}">
    <kp>1000000000000000000000000000.0</kp>
    <kd>1000000000000000000000000000.0</kd>
    <mu1>10.0</mu1>
    <mu2>10.0</mu2>
    <material>Gazebo/Grey</material>
  </gazebo>

  <joint name="left_wheel_joint${suffix}" type="continuous">
    <origin rpy="0 0 0" xyz="0 0.5 -0.125"/>
    <child link="left_wheel${suffix}"/>
    <parent link="base_link${suffix}"/>
    <axis rpy="0 0 0" xyz="0 1 0"/>
    <limit effort="10000" velocity="1000"/>
    <joint_properties damping="1.0" friction="1.0"/>
  </joint>

  <!-- Wheel Right -->
  <link name="right_wheel${suffix}">      
    <visual>
      <origin rpy="-1.5707 0 0" xyz="0 0 0"/>
      <geometry>
        <cylinder length="0.2" radius="0.2"/>
        <!--<mesh filename="model://robot/files/wheel.dae" scale="1.0 1.0 1.0"/> -->
      </geometry>
      <material name="black"/>
    </visual>
    <collision>
      <origin rpy="-1.5707 0 0" xyz="0 0 0"/>
      <geometry>
        <cylinder length="0.2" radius="0.2"/>
        <!--<mesh filename="model://robot/files/wheel.dae" scale="1.0 1.0 1.0"/> -->
      </geometry>
    </collision>
    <inertial>
      <origin rpy="-1.5707 0 0" xyz="0 0 0"/>
      <mass value="4.0"/>
      <inertia ixx="0.05333" ixy="0" ixz="0" iyy="0.05333" iyz="0" izz="0.08"/>
    </inertial>
  </link>

  <gazebo reference="right_wheel${suffix}">
    <kp>1000000000000000000000000000.0</kp>
    <kd>1000000000000000000000000000.0</kd>
    <mu1>10.0</mu1>
    <mu2>10.0</mu2>
    <material>Gazebo/Grey</material>
  </gazebo>

  <joint name="right_wheel_joint${suffix}" type="continuous">  
    <origin rpy="0 0 0" xyz="0 -0.5 -0.125"/>
    <child link="right_wheel${suffix}"/>
    <parent link="base_link${suffix}"/>
    <axis rpy="0 0 0" xyz="0 1 0"/>
    <limit effort="10000" velocity="1000"/>
    <joint_properties damping="1.0" friction="1.0"/>
  </joint>


  <!-- Caster Wheel Front -->
  <link name="front_caster${suffix}">
    <visual>
      <origin rpy="0 1.5707 1.5707" xyz="0 0 0"/>
      <geometry>          
        <cylinder length="0.1" radius="0.1"/>
      </geometry>
      <material name="black"/>
    </visual>
    <collision name="front_yaw_collision">
      <origin rpy="0 1.5707 1.5707" xyz="0 0 0"/>
      <geometry>
        <cylinder length="0.1" radius="0.1"/>
      </geometry>
    </collision>
    <inertial>
      <origin rpy="0 1.5707 1.5707" xyz="0 0 0"/>
      <mass value="0.001"/>
      <inertia ixx="5.145833333333334e-09" ixy="0" ixz="0" iyy="5.145833333333334e-09" iyz="0" izz="1.0125000000000003e-08"/>
    </inertial>
  </link>

  <joint name="front_caster_joint${suffix}" type="fixed">
    <child link="front_caster${suffix}"/>
    <parent link="base_link${suffix}"/>
    <joint_properties damping="0.0" friction="0.001"/>
  </joint>

  <gazebo reference="front_caster${suffix}">
    <kp>1000000000000000000000000000.0</kp>
    <kd>1000000000000000000000000000.0</kd>
    <mu1>0.5</mu1>
    <mu2>0.5</mu2>
  </gazebo>  

  <!-- Caster Wheel Back -->
  <link name="back_caster${suffix}">
    <visual>
      <origin rpy="0 1.5707 1.5707" xyz="0 0 0"/>
      <geometry>
        <cylinder length="0.1" radius="0.1"/>
      </geometry>
      <material name="black"/>
    </visual>
    <collision>
      <origin rpy="0 1.5707 1.5707" xyz="0 0 0"/>
      <geometry>
        <cylinder length="0.1" radius="0.1"/>
      </geometry>
    </collision>
    <inertial>
      <origin rpy="0 1.5707 1.5707" xyz="0 0 0"/>
      <mass value="0.001"/>
      <inertia ixx="5.145833333333334e-09" ixy="0" ixz="0" iyy="5.145833333333334e-09" iyz="0" izz="1.0125000000000003e-08"/>
    </inertial>
  </link>

  <joint name="back_caster_joint${suffix}" type="fixed">
        <child link="back_caster${suffix}"/>
        <parent link="base_link${suffix}"/>
        <joint_properties damping="0.0" friction="0.001"/>
    </joint>

  <gazebo reference="back_caster${suffix}">
    <kp>1000000000000000000000000000.0</kp>
    <kd>1000000000000000000000000000.0</kd>
    <mu1>0.5</mu1>
    <mu2>0.5</mu2>
  </gazebo>

  <!-- PLUGINS -->
  <gazebo>
    <plugin name="ground_truth" filename="libgazebo_ros_p3d.so">
      <ros>
        <namespace>small_robot${suffix}</namespace>
        <remapping>odom:=ground_truth</remapping>
      </ros>
      <frame_name>map</frame_name>
      <body_name>base_link${suffix}</body_name>
      <update_rate>100.0</update_rate>
      <gaussian_noise>0.01</gaussian_noise>
    </plugin>
  </gazebo>

  <!-- JOINT PUBLISHER -->
  <gazebo>
    <plugin name="joint_state${suffix}" filename="libgazebo_ros_joint_state_publisher.so">
      <ros>
          <namespace>/small_robot${suffix}</namespace>
      </ros>
      <update_rate>30</update_rate>

      <joint_name>left_wheel_joint${suffix}</joint_name>
      <joint_name>right_wheel_joint${suffix}</joint_name>
      
    </plugin>
  </gazebo>

  <!-- Differential drive -->
  <gazebo>
    <plugin filename="libgazebo_ros_diff_drive.so" name="diff_drive">
      <ros>
        <namespace>/small_robot${suffix}</namespace>
      </ros>

      <!-- wheels -->
      <left_joint>left_wheel_joint${suffix}</left_joint>
      <right_joint>right_wheel_joint${suffix}</right_joint>

      <!-- kinematics -->
      <wheel_separation>1</wheel_separation>
      <wheel_diameter>0.4</wheel_diameter>

      <!-- limits -->
      <max_wheel_torque>20.0</max_wheel_torque>
      <max_wheel_acceleration>1.0</max_wheel_acceleration>

      <!-- output -->
      <publish_odom>true</publish_odom>
      <publish_odom_tf>true</publish_odom_tf>

      <odometry_frame>odom</odometry_frame>
      <robot_base_frame>base_link${suffix}</robot_base_frame>
      <command_topic>cmd_vel</command_topic>

    </plugin>
  </gazebo>

  <!-- SENSORS-->

  <link name="laser_scan${suffix}">
    <visual>
      <origin rpy="0 0 0" xyz="0 0 0"/>
      <geometry>
        <box size="0.02 0.02 0.02"/>
      </geometry>
    </visual>
    <collision>
       <origin rpy="0 0 0" xyz="0 0 0"/>
      <geometry>
        <box size="0.02 0.02 0.02"/>
      </geometry>
    </collision>
    <inertial>
      <mass value="0.01"/>
      <origin rpy="0 0 0" xyz="0 0 0.0204"/>
      <inertia ixx="6.066578520833334e-06" ixy="0" ixz="0" iyy="6.066578520833334e-06" iyz="0" izz="9.365128684166666e-06"/>
    </inertial>
  </link>

  <joint name="laser_scan_joint${suffix}" type="fixed">
    <origin xyz="0 0 0.56" rpy="0 0 0" />
    <parent link="base_link${suffix}"/>
    <child link="laser_scan${suffix}"/>
  </joint>

  <gazebo reference="laser_scan${suffix}">
		<sensor name="sensor_ray" type="ray">
      <pose>0 0 0 0 0 0</pose>
      <ray>
        <scan>
          <horizontal>
            <samples>200</samples>
            <resolution>1.0</resolution>
            <min_angle>-3.14</min_angle>
            <max_angle>3.14</max_angle>
          </horizontal>
        </scan>
        <range>
          <min>0.1</min>
          <max>5.0</max>
        </range>
      </ray>
      <always_on>true</always_on>
      <visualize>true</visualize>
      <update_rate>20.0</update_rate>
      <plugin name="laser" filename="libgazebo_ros_ray_sensor.so">
        <ros>
          <namespace>/small_robot${suffix}</namespace>
          <remapping>~/out:=laser_scan</remapping>
        </ros>
        <output_type>sensor_msgs/LaserScan</output_type>
      </plugin>
    </sensor>
	</gazebo>

  
</robot>