#VRML_SIM R2022b utf8

EXTERNPROTO "https://raw.githubusercontent.com/cyberbotics/webots/R2022b/projects/objects/backgrounds/protos/TexturedBackground.proto"
EXTERNPROTO "https://raw.githubusercontent.com/cyberbotics/webots/R2022b/projects/objects/backgrounds/protos/TexturedBackgroundLight.proto"
EXTERNPROTO "https://raw.githubusercontent.com/cyberbotics/webots/R2022b/projects/objects/floors/protos/CircleArena.proto"

WorldInfo {
  info [
		 "Robotic simulators benchmark. Case N:20"
	]
  basicTimeStep 1
}
Viewpoint {
  orientation -0.32809 -0.112961 0.937868 3.69592
  position 9.18296 5.96196 8.73224
}
TexturedBackground {}
TexturedBackgroundLight {}
Floor {}

Robot {
  children [
    HingeJoint {
      jointParameters HingeJointParameters {
        axis 0 1 0
        anchor 0 0 -0.125
      }
      device [
        RotationalMotor {
          name "left wheel motor"
        }
      ]
      endPoint Solid {
        translation 0 0.5 -0.125
        children [
          DEF WHEEL Transform {
            rotation 1 0 0 1.5707996938995747
            children [
              Shape {
                appearance PBRAppearance {
                  baseColor 0 0 0
                  roughness 1
                  metalness 0
                }
                geometry Cylinder {
                  height 0.2
                  radius 0.2
                }
              }
            ]
          }
        ]
        name "left wheel"
        boundingObject USE WHEEL
        physics Physics {
          mass 4
        }
      }
    }
    HingeJoint {
      jointParameters HingeJointParameters {
        axis 0 1 0
        anchor 0 0 -0.125
      }
      device [
        RotationalMotor {
          name "right wheel motor"
        }
      ]
      endPoint Solid {
        translation 0 -0.5 -0.125
        children [
          USE WHEEL
        ]
        name "right wheel"
        boundingObject USE WHEEL
        physics Physics {
          mass 4
        }
      }
    }
    DEF CASTER_JOINT BallJoint {
      jointParameters BallJointParameters {
        anchor -0.4 0 -0.225
      }
      endPoint Solid {
        translation -0.4 0 -0.225
        children [
          Shape {
            appearance PBRAppearance {
            }
            geometry DEF CASTER_SPHERE Sphere {
              radius 0.1
              subdivision 2
            }
          }
        ]
        boundingObject USE CASTER_SPHERE
        physics Physics {
          mass 0.001
        }
      }
    }
    DEF FRONT_CASTER_JOINT BallJoint {
      jointParameters BallJointParameters {
        anchor 0.4 0 -0.225
      }
      endPoint Solid {
        translation 0.4 0 -0.225
        children [
          Shape {
            appearance PBRAppearance {
            }
            geometry DEF CASTER_SPHERE Sphere {
              radius 0.1
              subdivision 2
            }
          }
        ]
        boundingObject USE CASTER_SPHERE
        physics Physics {
          mass 0.001
        }
      }
    }
    Transform {
      translation 0 0 0.0
      children [
        Shape {
          appearance PBRAppearance {
            baseColor 1 0 0
            roughness 1
            metalness 0
          }
          geometry DEF BODY Box {
            size 1.0 1.0 0.55
          }
        }
      ]
    }
    Camera {
        name "cam"
        translation 0.5 0 0.28
        fieldOfView 0.87
        width 324
        height 324
    }
    Gyro {
    }
    InertialUnit {
    }
    Accelerometer {
    }
    GPS {
    }
    LED {
    }
    Lidar {
      name "LDS-01"
      translation 0.5 0 0.2
      fieldOfView 6.2832
      maxRange 5.0
      minRange 1.0
      horizontalResolution 200
    }
    DistanceSensor {
      translation 0.042 0.02 0.063
      rotation 0 0 1 0.5236003061004253
      children [
        DEF SENSOR Transform {
          rotation 0 1 0 1.5708
          children [
            Shape {
              appearance PBRAppearance {
                baseColor 1 1 0
                roughness 1
                metalness 0
              }
              geometry Cylinder {
                height 0.004
                radius 0.008
              }
            }
          ]
        }
      ]
      name "ds0"
      lookupTable [
        0 1020 0
        0.05 1020 0
        0.15 0 0
      ]
      numberOfRays 2
      aperture 1
    }
    DistanceSensor {
      translation 0.042 -0.02 0.063
      rotation 0 0 1 -0.5235996938995747
      children [
        USE SENSOR
      ]
      name "ds1"
      lookupTable [
        0 1020 0
        0.05 1020 0
        0.15 0 0
      ]
      numberOfRays 2
      aperture 1
    }
  ]
  boundingObject Transform {
    translation 0 0 0
    children [
      USE BODY
    ]
  }
  physics Physics {
    mass 15.0
  }
  supervisor TRUE
  controller "<extern>"
  name "small_robot00"
  translation 0.0 0.0 0.5
	rotation 0 0 1 0.0
}

Robot {
  children [
    HingeJoint {
      jointParameters HingeJointParameters {
        axis 0 1 0
        anchor 0 0 -0.125
      }
      device [
        RotationalMotor {
          name "left wheel motor"
        }
      ]
      endPoint Solid {
        translation 0 0.5 -0.125
        children [
          DEF WHEEL Transform {
            rotation 1 0 0 1.5707996938995747
            children [
              Shape {
                appearance PBRAppearance {
                  baseColor 0 0 0
                  roughness 1
                  metalness 0
                }
                geometry Cylinder {
                  height 0.2
                  radius 0.2
                }
              }
            ]
          }
        ]
        name "left wheel"
        boundingObject USE WHEEL
        physics Physics {
          mass 4
        }
      }
    }
    HingeJoint {
      jointParameters HingeJointParameters {
        axis 0 1 0
        anchor 0 0 -0.125
      }
      device [
        RotationalMotor {
          name "right wheel motor"
        }
      ]
      endPoint Solid {
        translation 0 -0.5 -0.125
        children [
          USE WHEEL
        ]
        name "right wheel"
        boundingObject USE WHEEL
        physics Physics {
          mass 4
        }
      }
    }
    DEF CASTER_JOINT BallJoint {
      jointParameters BallJointParameters {
        anchor -0.4 0 -0.225
      }
      endPoint Solid {
        translation -0.4 0 -0.225
        children [
          Shape {
            appearance PBRAppearance {
            }
            geometry DEF CASTER_SPHERE Sphere {
              radius 0.1
              subdivision 2
            }
          }
        ]
        boundingObject USE CASTER_SPHERE
        physics Physics {
          mass 0.001
        }
      }
    }
    DEF FRONT_CASTER_JOINT BallJoint {
      jointParameters BallJointParameters {
        anchor 0.4 0 -0.225
      }
      endPoint Solid {
        translation 0.4 0 -0.225
        children [
          Shape {
            appearance PBRAppearance {
            }
            geometry DEF CASTER_SPHERE Sphere {
              radius 0.1
              subdivision 2
            }
          }
        ]
        boundingObject USE CASTER_SPHERE
        physics Physics {
          mass 0.001
        }
      }
    }
    Transform {
      translation 0 0 0.0
      children [
        Shape {
          appearance PBRAppearance {
            baseColor 1 0 0
            roughness 1
            metalness 0
          }
          geometry DEF BODY Box {
            size 1.0 1.0 0.55
          }
        }
      ]
    }
    Camera {
        name "cam"
        translation 0.5 0 0.28
        fieldOfView 0.87
        width 324
        height 324
    }
    Gyro {
    }
    InertialUnit {
    }
    Accelerometer {
    }
    GPS {
    }
    LED {
    }
    Lidar {
      name "LDS-01"
      translation 0.5 0 0.2
      fieldOfView 6.2832
      maxRange 5.0
      minRange 1.0
      horizontalResolution 200
    }
    DistanceSensor {
      translation 0.042 0.02 0.063
      rotation 0 0 1 0.5236003061004253
      children [
        DEF SENSOR Transform {
          rotation 0 1 0 1.5708
          children [
            Shape {
              appearance PBRAppearance {
                baseColor 1 1 0
                roughness 1
                metalness 0
              }
              geometry Cylinder {
                height 0.004
                radius 0.008
              }
            }
          ]
        }
      ]
      name "ds0"
      lookupTable [
        0 1020 0
        0.05 1020 0
        0.15 0 0
      ]
      numberOfRays 2
      aperture 1
    }
    DistanceSensor {
      translation 0.042 -0.02 0.063
      rotation 0 0 1 -0.5235996938995747
      children [
        USE SENSOR
      ]
      name "ds1"
      lookupTable [
        0 1020 0
        0.05 1020 0
        0.15 0 0
      ]
      numberOfRays 2
      aperture 1
    }
  ]
  boundingObject Transform {
    translation 0 0 0
    children [
      USE BODY
    ]
  }
  physics Physics {
    mass 15.0
  }
  controller "<extern>"
  name "small_robot01"
  translation 1.5 0.0 0.5
	rotation 0 0 1 0.0
}

Robot {
  children [
    HingeJoint {
      jointParameters HingeJointParameters {
        axis 0 1 0
        anchor 0 0 -0.125
      }
      device [
        RotationalMotor {
          name "left wheel motor"
        }
      ]
      endPoint Solid {
        translation 0 0.5 -0.125
        children [
          DEF WHEEL Transform {
            rotation 1 0 0 1.5707996938995747
            children [
              Shape {
                appearance PBRAppearance {
                  baseColor 0 0 0
                  roughness 1
                  metalness 0
                }
                geometry Cylinder {
                  height 0.2
                  radius 0.2
                }
              }
            ]
          }
        ]
        name "left wheel"
        boundingObject USE WHEEL
        physics Physics {
          mass 4
        }
      }
    }
    HingeJoint {
      jointParameters HingeJointParameters {
        axis 0 1 0
        anchor 0 0 -0.125
      }
      device [
        RotationalMotor {
          name "right wheel motor"
        }
      ]
      endPoint Solid {
        translation 0 -0.5 -0.125
        children [
          USE WHEEL
        ]
        name "right wheel"
        boundingObject USE WHEEL
        physics Physics {
          mass 4
        }
      }
    }
    DEF CASTER_JOINT BallJoint {
      jointParameters BallJointParameters {
        anchor -0.4 0 -0.225
      }
      endPoint Solid {
        translation -0.4 0 -0.225
        children [
          Shape {
            appearance PBRAppearance {
            }
            geometry DEF CASTER_SPHERE Sphere {
              radius 0.1
              subdivision 2
            }
          }
        ]
        boundingObject USE CASTER_SPHERE
        physics Physics {
          mass 0.001
        }
      }
    }
    DEF FRONT_CASTER_JOINT BallJoint {
      jointParameters BallJointParameters {
        anchor 0.4 0 -0.225
      }
      endPoint Solid {
        translation 0.4 0 -0.225
        children [
          Shape {
            appearance PBRAppearance {
            }
            geometry DEF CASTER_SPHERE Sphere {
              radius 0.1
              subdivision 2
            }
          }
        ]
        boundingObject USE CASTER_SPHERE
        physics Physics {
          mass 0.001
        }
      }
    }
    Transform {
      translation 0 0 0.0
      children [
        Shape {
          appearance PBRAppearance {
            baseColor 1 0 0
            roughness 1
            metalness 0
          }
          geometry DEF BODY Box {
            size 1.0 1.0 0.55
          }
        }
      ]
    }
    Camera {
        name "cam"
        translation 0.5 0 0.28
        fieldOfView 0.87
        width 324
        height 324
    }
    Gyro {
    }
    InertialUnit {
    }
    Accelerometer {
    }
    GPS {
    }
    LED {
    }
    Lidar {
      name "LDS-01"
      translation 0.5 0 0.2
      fieldOfView 6.2832
      maxRange 5.0
      minRange 1.0
      horizontalResolution 200
    }
    DistanceSensor {
      translation 0.042 0.02 0.063
      rotation 0 0 1 0.5236003061004253
      children [
        DEF SENSOR Transform {
          rotation 0 1 0 1.5708
          children [
            Shape {
              appearance PBRAppearance {
                baseColor 1 1 0
                roughness 1
                metalness 0
              }
              geometry Cylinder {
                height 0.004
                radius 0.008
              }
            }
          ]
        }
      ]
      name "ds0"
      lookupTable [
        0 1020 0
        0.05 1020 0
        0.15 0 0
      ]
      numberOfRays 2
      aperture 1
    }
    DistanceSensor {
      translation 0.042 -0.02 0.063
      rotation 0 0 1 -0.5235996938995747
      children [
        USE SENSOR
      ]
      name "ds1"
      lookupTable [
        0 1020 0
        0.05 1020 0
        0.15 0 0
      ]
      numberOfRays 2
      aperture 1
    }
  ]
  boundingObject Transform {
    translation 0 0 0
    children [
      USE BODY
    ]
  }
  physics Physics {
    mass 15.0
  }
  controller "<extern>"
  name "small_robot02"
  translation 1.5 1.5 0.5
	rotation 0 0 1 0.0
}

Robot {
  children [
    HingeJoint {
      jointParameters HingeJointParameters {
        axis 0 1 0
        anchor 0 0 -0.125
      }
      device [
        RotationalMotor {
          name "left wheel motor"
        }
      ]
      endPoint Solid {
        translation 0 0.5 -0.125
        children [
          DEF WHEEL Transform {
            rotation 1 0 0 1.5707996938995747
            children [
              Shape {
                appearance PBRAppearance {
                  baseColor 0 0 0
                  roughness 1
                  metalness 0
                }
                geometry Cylinder {
                  height 0.2
                  radius 0.2
                }
              }
            ]
          }
        ]
        name "left wheel"
        boundingObject USE WHEEL
        physics Physics {
          mass 4
        }
      }
    }
    HingeJoint {
      jointParameters HingeJointParameters {
        axis 0 1 0
        anchor 0 0 -0.125
      }
      device [
        RotationalMotor {
          name "right wheel motor"
        }
      ]
      endPoint Solid {
        translation 0 -0.5 -0.125
        children [
          USE WHEEL
        ]
        name "right wheel"
        boundingObject USE WHEEL
        physics Physics {
          mass 4
        }
      }
    }
    DEF CASTER_JOINT BallJoint {
      jointParameters BallJointParameters {
        anchor -0.4 0 -0.225
      }
      endPoint Solid {
        translation -0.4 0 -0.225
        children [
          Shape {
            appearance PBRAppearance {
            }
            geometry DEF CASTER_SPHERE Sphere {
              radius 0.1
              subdivision 2
            }
          }
        ]
        boundingObject USE CASTER_SPHERE
        physics Physics {
          mass 0.001
        }
      }
    }
    DEF FRONT_CASTER_JOINT BallJoint {
      jointParameters BallJointParameters {
        anchor 0.4 0 -0.225
      }
      endPoint Solid {
        translation 0.4 0 -0.225
        children [
          Shape {
            appearance PBRAppearance {
            }
            geometry DEF CASTER_SPHERE Sphere {
              radius 0.1
              subdivision 2
            }
          }
        ]
        boundingObject USE CASTER_SPHERE
        physics Physics {
          mass 0.001
        }
      }
    }
    Transform {
      translation 0 0 0.0
      children [
        Shape {
          appearance PBRAppearance {
            baseColor 1 0 0
            roughness 1
            metalness 0
          }
          geometry DEF BODY Box {
            size 1.0 1.0 0.55
          }
        }
      ]
    }
    Camera {
        name "cam"
        translation 0.5 0 0.28
        fieldOfView 0.87
        width 324
        height 324
    }
    Gyro {
    }
    InertialUnit {
    }
    Accelerometer {
    }
    GPS {
    }
    LED {
    }
    Lidar {
      name "LDS-01"
      translation 0.5 0 0.2
      fieldOfView 6.2832
      maxRange 5.0
      minRange 1.0
      horizontalResolution 200
    }
    DistanceSensor {
      translation 0.042 0.02 0.063
      rotation 0 0 1 0.5236003061004253
      children [
        DEF SENSOR Transform {
          rotation 0 1 0 1.5708
          children [
            Shape {
              appearance PBRAppearance {
                baseColor 1 1 0
                roughness 1
                metalness 0
              }
              geometry Cylinder {
                height 0.004
                radius 0.008
              }
            }
          ]
        }
      ]
      name "ds0"
      lookupTable [
        0 1020 0
        0.05 1020 0
        0.15 0 0
      ]
      numberOfRays 2
      aperture 1
    }
    DistanceSensor {
      translation 0.042 -0.02 0.063
      rotation 0 0 1 -0.5235996938995747
      children [
        USE SENSOR
      ]
      name "ds1"
      lookupTable [
        0 1020 0
        0.05 1020 0
        0.15 0 0
      ]
      numberOfRays 2
      aperture 1
    }
  ]
  boundingObject Transform {
    translation 0 0 0
    children [
      USE BODY
    ]
  }
  physics Physics {
    mass 15.0
  }
  controller "<extern>"
  name "small_robot03"
  translation 0.0 1.5 0.5
	rotation 0 0 1 0.0
}

Robot {
  children [
    HingeJoint {
      jointParameters HingeJointParameters {
        axis 0 1 0
        anchor 0 0 -0.125
      }
      device [
        RotationalMotor {
          name "left wheel motor"
        }
      ]
      endPoint Solid {
        translation 0 0.5 -0.125
        children [
          DEF WHEEL Transform {
            rotation 1 0 0 1.5707996938995747
            children [
              Shape {
                appearance PBRAppearance {
                  baseColor 0 0 0
                  roughness 1
                  metalness 0
                }
                geometry Cylinder {
                  height 0.2
                  radius 0.2
                }
              }
            ]
          }
        ]
        name "left wheel"
        boundingObject USE WHEEL
        physics Physics {
          mass 4
        }
      }
    }
    HingeJoint {
      jointParameters HingeJointParameters {
        axis 0 1 0
        anchor 0 0 -0.125
      }
      device [
        RotationalMotor {
          name "right wheel motor"
        }
      ]
      endPoint Solid {
        translation 0 -0.5 -0.125
        children [
          USE WHEEL
        ]
        name "right wheel"
        boundingObject USE WHEEL
        physics Physics {
          mass 4
        }
      }
    }
    DEF CASTER_JOINT BallJoint {
      jointParameters BallJointParameters {
        anchor -0.4 0 -0.225
      }
      endPoint Solid {
        translation -0.4 0 -0.225
        children [
          Shape {
            appearance PBRAppearance {
            }
            geometry DEF CASTER_SPHERE Sphere {
              radius 0.1
              subdivision 2
            }
          }
        ]
        boundingObject USE CASTER_SPHERE
        physics Physics {
          mass 0.001
        }
      }
    }
    DEF FRONT_CASTER_JOINT BallJoint {
      jointParameters BallJointParameters {
        anchor 0.4 0 -0.225
      }
      endPoint Solid {
        translation 0.4 0 -0.225
        children [
          Shape {
            appearance PBRAppearance {
            }
            geometry DEF CASTER_SPHERE Sphere {
              radius 0.1
              subdivision 2
            }
          }
        ]
        boundingObject USE CASTER_SPHERE
        physics Physics {
          mass 0.001
        }
      }
    }
    Transform {
      translation 0 0 0.0
      children [
        Shape {
          appearance PBRAppearance {
            baseColor 1 0 0
            roughness 1
            metalness 0
          }
          geometry DEF BODY Box {
            size 1.0 1.0 0.55
          }
        }
      ]
    }
    Camera {
        name "cam"
        translation 0.5 0 0.28
        fieldOfView 0.87
        width 324
        height 324
    }
    Gyro {
    }
    InertialUnit {
    }
    Accelerometer {
    }
    GPS {
    }
    LED {
    }
    Lidar {
      name "LDS-01"
      translation 0.5 0 0.2
      fieldOfView 6.2832
      maxRange 5.0
      minRange 1.0
      horizontalResolution 200
    }
    DistanceSensor {
      translation 0.042 0.02 0.063
      rotation 0 0 1 0.5236003061004253
      children [
        DEF SENSOR Transform {
          rotation 0 1 0 1.5708
          children [
            Shape {
              appearance PBRAppearance {
                baseColor 1 1 0
                roughness 1
                metalness 0
              }
              geometry Cylinder {
                height 0.004
                radius 0.008
              }
            }
          ]
        }
      ]
      name "ds0"
      lookupTable [
        0 1020 0
        0.05 1020 0
        0.15 0 0
      ]
      numberOfRays 2
      aperture 1
    }
    DistanceSensor {
      translation 0.042 -0.02 0.063
      rotation 0 0 1 -0.5235996938995747
      children [
        USE SENSOR
      ]
      name "ds1"
      lookupTable [
        0 1020 0
        0.05 1020 0
        0.15 0 0
      ]
      numberOfRays 2
      aperture 1
    }
  ]
  boundingObject Transform {
    translation 0 0 0
    children [
      USE BODY
    ]
  }
  physics Physics {
    mass 15.0
  }
  controller "<extern>"
  name "small_robot04"
  translation -1.5 1.5 0.5
	rotation 0 0 1 0.0
}

Robot {
  children [
    HingeJoint {
      jointParameters HingeJointParameters {
        axis 0 1 0
        anchor 0 0 -0.125
      }
      device [
        RotationalMotor {
          name "left wheel motor"
        }
      ]
      endPoint Solid {
        translation 0 0.5 -0.125
        children [
          DEF WHEEL Transform {
            rotation 1 0 0 1.5707996938995747
            children [
              Shape {
                appearance PBRAppearance {
                  baseColor 0 0 0
                  roughness 1
                  metalness 0
                }
                geometry Cylinder {
                  height 0.2
                  radius 0.2
                }
              }
            ]
          }
        ]
        name "left wheel"
        boundingObject USE WHEEL
        physics Physics {
          mass 4
        }
      }
    }
    HingeJoint {
      jointParameters HingeJointParameters {
        axis 0 1 0
        anchor 0 0 -0.125
      }
      device [
        RotationalMotor {
          name "right wheel motor"
        }
      ]
      endPoint Solid {
        translation 0 -0.5 -0.125
        children [
          USE WHEEL
        ]
        name "right wheel"
        boundingObject USE WHEEL
        physics Physics {
          mass 4
        }
      }
    }
    DEF CASTER_JOINT BallJoint {
      jointParameters BallJointParameters {
        anchor -0.4 0 -0.225
      }
      endPoint Solid {
        translation -0.4 0 -0.225
        children [
          Shape {
            appearance PBRAppearance {
            }
            geometry DEF CASTER_SPHERE Sphere {
              radius 0.1
              subdivision 2
            }
          }
        ]
        boundingObject USE CASTER_SPHERE
        physics Physics {
          mass 0.001
        }
      }
    }
    DEF FRONT_CASTER_JOINT BallJoint {
      jointParameters BallJointParameters {
        anchor 0.4 0 -0.225
      }
      endPoint Solid {
        translation 0.4 0 -0.225
        children [
          Shape {
            appearance PBRAppearance {
            }
            geometry DEF CASTER_SPHERE Sphere {
              radius 0.1
              subdivision 2
            }
          }
        ]
        boundingObject USE CASTER_SPHERE
        physics Physics {
          mass 0.001
        }
      }
    }
    Transform {
      translation 0 0 0.0
      children [
        Shape {
          appearance PBRAppearance {
            baseColor 1 0 0
            roughness 1
            metalness 0
          }
          geometry DEF BODY Box {
            size 1.0 1.0 0.55
          }
        }
      ]
    }
    Camera {
        name "cam"
        translation 0.5 0 0.28
        fieldOfView 0.87
        width 324
        height 324
    }
    Gyro {
    }
    InertialUnit {
    }
    Accelerometer {
    }
    GPS {
    }
    LED {
    }
    Lidar {
      name "LDS-01"
      translation 0.5 0 0.2
      fieldOfView 6.2832
      maxRange 5.0
      minRange 1.0
      horizontalResolution 200
    }
    DistanceSensor {
      translation 0.042 0.02 0.063
      rotation 0 0 1 0.5236003061004253
      children [
        DEF SENSOR Transform {
          rotation 0 1 0 1.5708
          children [
            Shape {
              appearance PBRAppearance {
                baseColor 1 1 0
                roughness 1
                metalness 0
              }
              geometry Cylinder {
                height 0.004
                radius 0.008
              }
            }
          ]
        }
      ]
      name "ds0"
      lookupTable [
        0 1020 0
        0.05 1020 0
        0.15 0 0
      ]
      numberOfRays 2
      aperture 1
    }
    DistanceSensor {
      translation 0.042 -0.02 0.063
      rotation 0 0 1 -0.5235996938995747
      children [
        USE SENSOR
      ]
      name "ds1"
      lookupTable [
        0 1020 0
        0.05 1020 0
        0.15 0 0
      ]
      numberOfRays 2
      aperture 1
    }
  ]
  boundingObject Transform {
    translation 0 0 0
    children [
      USE BODY
    ]
  }
  physics Physics {
    mass 15.0
  }
  controller "<extern>"
  name "small_robot05"
  translation -1.5 0.0 0.5
	rotation 0 0 1 0.0
}

Robot {
  children [
    HingeJoint {
      jointParameters HingeJointParameters {
        axis 0 1 0
        anchor 0 0 -0.125
      }
      device [
        RotationalMotor {
          name "left wheel motor"
        }
      ]
      endPoint Solid {
        translation 0 0.5 -0.125
        children [
          DEF WHEEL Transform {
            rotation 1 0 0 1.5707996938995747
            children [
              Shape {
                appearance PBRAppearance {
                  baseColor 0 0 0
                  roughness 1
                  metalness 0
                }
                geometry Cylinder {
                  height 0.2
                  radius 0.2
                }
              }
            ]
          }
        ]
        name "left wheel"
        boundingObject USE WHEEL
        physics Physics {
          mass 4
        }
      }
    }
    HingeJoint {
      jointParameters HingeJointParameters {
        axis 0 1 0
        anchor 0 0 -0.125
      }
      device [
        RotationalMotor {
          name "right wheel motor"
        }
      ]
      endPoint Solid {
        translation 0 -0.5 -0.125
        children [
          USE WHEEL
        ]
        name "right wheel"
        boundingObject USE WHEEL
        physics Physics {
          mass 4
        }
      }
    }
    DEF CASTER_JOINT BallJoint {
      jointParameters BallJointParameters {
        anchor -0.4 0 -0.225
      }
      endPoint Solid {
        translation -0.4 0 -0.225
        children [
          Shape {
            appearance PBRAppearance {
            }
            geometry DEF CASTER_SPHERE Sphere {
              radius 0.1
              subdivision 2
            }
          }
        ]
        boundingObject USE CASTER_SPHERE
        physics Physics {
          mass 0.001
        }
      }
    }
    DEF FRONT_CASTER_JOINT BallJoint {
      jointParameters BallJointParameters {
        anchor 0.4 0 -0.225
      }
      endPoint Solid {
        translation 0.4 0 -0.225
        children [
          Shape {
            appearance PBRAppearance {
            }
            geometry DEF CASTER_SPHERE Sphere {
              radius 0.1
              subdivision 2
            }
          }
        ]
        boundingObject USE CASTER_SPHERE
        physics Physics {
          mass 0.001
        }
      }
    }
    Transform {
      translation 0 0 0.0
      children [
        Shape {
          appearance PBRAppearance {
            baseColor 1 0 0
            roughness 1
            metalness 0
          }
          geometry DEF BODY Box {
            size 1.0 1.0 0.55
          }
        }
      ]
    }
    Camera {
        name "cam"
        translation 0.5 0 0.28
        fieldOfView 0.87
        width 324
        height 324
    }
    Gyro {
    }
    InertialUnit {
    }
    Accelerometer {
    }
    GPS {
    }
    LED {
    }
    Lidar {
      name "LDS-01"
      translation 0.5 0 0.2
      fieldOfView 6.2832
      maxRange 5.0
      minRange 1.0
      horizontalResolution 200
    }
    DistanceSensor {
      translation 0.042 0.02 0.063
      rotation 0 0 1 0.5236003061004253
      children [
        DEF SENSOR Transform {
          rotation 0 1 0 1.5708
          children [
            Shape {
              appearance PBRAppearance {
                baseColor 1 1 0
                roughness 1
                metalness 0
              }
              geometry Cylinder {
                height 0.004
                radius 0.008
              }
            }
          ]
        }
      ]
      name "ds0"
      lookupTable [
        0 1020 0
        0.05 1020 0
        0.15 0 0
      ]
      numberOfRays 2
      aperture 1
    }
    DistanceSensor {
      translation 0.042 -0.02 0.063
      rotation 0 0 1 -0.5235996938995747
      children [
        USE SENSOR
      ]
      name "ds1"
      lookupTable [
        0 1020 0
        0.05 1020 0
        0.15 0 0
      ]
      numberOfRays 2
      aperture 1
    }
  ]
  boundingObject Transform {
    translation 0 0 0
    children [
      USE BODY
    ]
  }
  physics Physics {
    mass 15.0
  }
  controller "<extern>"
  name "small_robot06"
  translation -1.5 -1.5 0.5
	rotation 0 0 1 0.0
}

Robot {
  children [
    HingeJoint {
      jointParameters HingeJointParameters {
        axis 0 1 0
        anchor 0 0 -0.125
      }
      device [
        RotationalMotor {
          name "left wheel motor"
        }
      ]
      endPoint Solid {
        translation 0 0.5 -0.125
        children [
          DEF WHEEL Transform {
            rotation 1 0 0 1.5707996938995747
            children [
              Shape {
                appearance PBRAppearance {
                  baseColor 0 0 0
                  roughness 1
                  metalness 0
                }
                geometry Cylinder {
                  height 0.2
                  radius 0.2
                }
              }
            ]
          }
        ]
        name "left wheel"
        boundingObject USE WHEEL
        physics Physics {
          mass 4
        }
      }
    }
    HingeJoint {
      jointParameters HingeJointParameters {
        axis 0 1 0
        anchor 0 0 -0.125
      }
      device [
        RotationalMotor {
          name "right wheel motor"
        }
      ]
      endPoint Solid {
        translation 0 -0.5 -0.125
        children [
          USE WHEEL
        ]
        name "right wheel"
        boundingObject USE WHEEL
        physics Physics {
          mass 4
        }
      }
    }
    DEF CASTER_JOINT BallJoint {
      jointParameters BallJointParameters {
        anchor -0.4 0 -0.225
      }
      endPoint Solid {
        translation -0.4 0 -0.225
        children [
          Shape {
            appearance PBRAppearance {
            }
            geometry DEF CASTER_SPHERE Sphere {
              radius 0.1
              subdivision 2
            }
          }
        ]
        boundingObject USE CASTER_SPHERE
        physics Physics {
          mass 0.001
        }
      }
    }
    DEF FRONT_CASTER_JOINT BallJoint {
      jointParameters BallJointParameters {
        anchor 0.4 0 -0.225
      }
      endPoint Solid {
        translation 0.4 0 -0.225
        children [
          Shape {
            appearance PBRAppearance {
            }
            geometry DEF CASTER_SPHERE Sphere {
              radius 0.1
              subdivision 2
            }
          }
        ]
        boundingObject USE CASTER_SPHERE
        physics Physics {
          mass 0.001
        }
      }
    }
    Transform {
      translation 0 0 0.0
      children [
        Shape {
          appearance PBRAppearance {
            baseColor 1 0 0
            roughness 1
            metalness 0
          }
          geometry DEF BODY Box {
            size 1.0 1.0 0.55
          }
        }
      ]
    }
    Camera {
        name "cam"
        translation 0.5 0 0.28
        fieldOfView 0.87
        width 324
        height 324
    }
    Gyro {
    }
    InertialUnit {
    }
    Accelerometer {
    }
    GPS {
    }
    LED {
    }
    Lidar {
      name "LDS-01"
      translation 0.5 0 0.2
      fieldOfView 6.2832
      maxRange 5.0
      minRange 1.0
      horizontalResolution 200
    }
    DistanceSensor {
      translation 0.042 0.02 0.063
      rotation 0 0 1 0.5236003061004253
      children [
        DEF SENSOR Transform {
          rotation 0 1 0 1.5708
          children [
            Shape {
              appearance PBRAppearance {
                baseColor 1 1 0
                roughness 1
                metalness 0
              }
              geometry Cylinder {
                height 0.004
                radius 0.008
              }
            }
          ]
        }
      ]
      name "ds0"
      lookupTable [
        0 1020 0
        0.05 1020 0
        0.15 0 0
      ]
      numberOfRays 2
      aperture 1
    }
    DistanceSensor {
      translation 0.042 -0.02 0.063
      rotation 0 0 1 -0.5235996938995747
      children [
        USE SENSOR
      ]
      name "ds1"
      lookupTable [
        0 1020 0
        0.05 1020 0
        0.15 0 0
      ]
      numberOfRays 2
      aperture 1
    }
  ]
  boundingObject Transform {
    translation 0 0 0
    children [
      USE BODY
    ]
  }
  physics Physics {
    mass 15.0
  }
  controller "<extern>"
  name "small_robot07"
  translation 0.0 -1.5 0.5
	rotation 0 0 1 0.0
}

Robot {
  children [
    HingeJoint {
      jointParameters HingeJointParameters {
        axis 0 1 0
        anchor 0 0 -0.125
      }
      device [
        RotationalMotor {
          name "left wheel motor"
        }
      ]
      endPoint Solid {
        translation 0 0.5 -0.125
        children [
          DEF WHEEL Transform {
            rotation 1 0 0 1.5707996938995747
            children [
              Shape {
                appearance PBRAppearance {
                  baseColor 0 0 0
                  roughness 1
                  metalness 0
                }
                geometry Cylinder {
                  height 0.2
                  radius 0.2
                }
              }
            ]
          }
        ]
        name "left wheel"
        boundingObject USE WHEEL
        physics Physics {
          mass 4
        }
      }
    }
    HingeJoint {
      jointParameters HingeJointParameters {
        axis 0 1 0
        anchor 0 0 -0.125
      }
      device [
        RotationalMotor {
          name "right wheel motor"
        }
      ]
      endPoint Solid {
        translation 0 -0.5 -0.125
        children [
          USE WHEEL
        ]
        name "right wheel"
        boundingObject USE WHEEL
        physics Physics {
          mass 4
        }
      }
    }
    DEF CASTER_JOINT BallJoint {
      jointParameters BallJointParameters {
        anchor -0.4 0 -0.225
      }
      endPoint Solid {
        translation -0.4 0 -0.225
        children [
          Shape {
            appearance PBRAppearance {
            }
            geometry DEF CASTER_SPHERE Sphere {
              radius 0.1
              subdivision 2
            }
          }
        ]
        boundingObject USE CASTER_SPHERE
        physics Physics {
          mass 0.001
        }
      }
    }
    DEF FRONT_CASTER_JOINT BallJoint {
      jointParameters BallJointParameters {
        anchor 0.4 0 -0.225
      }
      endPoint Solid {
        translation 0.4 0 -0.225
        children [
          Shape {
            appearance PBRAppearance {
            }
            geometry DEF CASTER_SPHERE Sphere {
              radius 0.1
              subdivision 2
            }
          }
        ]
        boundingObject USE CASTER_SPHERE
        physics Physics {
          mass 0.001
        }
      }
    }
    Transform {
      translation 0 0 0.0
      children [
        Shape {
          appearance PBRAppearance {
            baseColor 1 0 0
            roughness 1
            metalness 0
          }
          geometry DEF BODY Box {
            size 1.0 1.0 0.55
          }
        }
      ]
    }
    Camera {
        name "cam"
        translation 0.5 0 0.28
        fieldOfView 0.87
        width 324
        height 324
    }
    Gyro {
    }
    InertialUnit {
    }
    Accelerometer {
    }
    GPS {
    }
    LED {
    }
    Lidar {
      name "LDS-01"
      translation 0.5 0 0.2
      fieldOfView 6.2832
      maxRange 5.0
      minRange 1.0
      horizontalResolution 200
    }
    DistanceSensor {
      translation 0.042 0.02 0.063
      rotation 0 0 1 0.5236003061004253
      children [
        DEF SENSOR Transform {
          rotation 0 1 0 1.5708
          children [
            Shape {
              appearance PBRAppearance {
                baseColor 1 1 0
                roughness 1
                metalness 0
              }
              geometry Cylinder {
                height 0.004
                radius 0.008
              }
            }
          ]
        }
      ]
      name "ds0"
      lookupTable [
        0 1020 0
        0.05 1020 0
        0.15 0 0
      ]
      numberOfRays 2
      aperture 1
    }
    DistanceSensor {
      translation 0.042 -0.02 0.063
      rotation 0 0 1 -0.5235996938995747
      children [
        USE SENSOR
      ]
      name "ds1"
      lookupTable [
        0 1020 0
        0.05 1020 0
        0.15 0 0
      ]
      numberOfRays 2
      aperture 1
    }
  ]
  boundingObject Transform {
    translation 0 0 0
    children [
      USE BODY
    ]
  }
  physics Physics {
    mass 15.0
  }
  controller "<extern>"
  name "small_robot08"
  translation 1.5 -1.5 0.5
	rotation 0 0 1 0.0
}

Robot {
  children [
    HingeJoint {
      jointParameters HingeJointParameters {
        axis 0 1 0
        anchor 0 0 -0.125
      }
      device [
        RotationalMotor {
          name "left wheel motor"
        }
      ]
      endPoint Solid {
        translation 0 0.5 -0.125
        children [
          DEF WHEEL Transform {
            rotation 1 0 0 1.5707996938995747
            children [
              Shape {
                appearance PBRAppearance {
                  baseColor 0 0 0
                  roughness 1
                  metalness 0
                }
                geometry Cylinder {
                  height 0.2
                  radius 0.2
                }
              }
            ]
          }
        ]
        name "left wheel"
        boundingObject USE WHEEL
        physics Physics {
          mass 4
        }
      }
    }
    HingeJoint {
      jointParameters HingeJointParameters {
        axis 0 1 0
        anchor 0 0 -0.125
      }
      device [
        RotationalMotor {
          name "right wheel motor"
        }
      ]
      endPoint Solid {
        translation 0 -0.5 -0.125
        children [
          USE WHEEL
        ]
        name "right wheel"
        boundingObject USE WHEEL
        physics Physics {
          mass 4
        }
      }
    }
    DEF CASTER_JOINT BallJoint {
      jointParameters BallJointParameters {
        anchor -0.4 0 -0.225
      }
      endPoint Solid {
        translation -0.4 0 -0.225
        children [
          Shape {
            appearance PBRAppearance {
            }
            geometry DEF CASTER_SPHERE Sphere {
              radius 0.1
              subdivision 2
            }
          }
        ]
        boundingObject USE CASTER_SPHERE
        physics Physics {
          mass 0.001
        }
      }
    }
    DEF FRONT_CASTER_JOINT BallJoint {
      jointParameters BallJointParameters {
        anchor 0.4 0 -0.225
      }
      endPoint Solid {
        translation 0.4 0 -0.225
        children [
          Shape {
            appearance PBRAppearance {
            }
            geometry DEF CASTER_SPHERE Sphere {
              radius 0.1
              subdivision 2
            }
          }
        ]
        boundingObject USE CASTER_SPHERE
        physics Physics {
          mass 0.001
        }
      }
    }
    Transform {
      translation 0 0 0.0
      children [
        Shape {
          appearance PBRAppearance {
            baseColor 1 0 0
            roughness 1
            metalness 0
          }
          geometry DEF BODY Box {
            size 1.0 1.0 0.55
          }
        }
      ]
    }
    Camera {
        name "cam"
        translation 0.5 0 0.28
        fieldOfView 0.87
        width 324
        height 324
    }
    Gyro {
    }
    InertialUnit {
    }
    Accelerometer {
    }
    GPS {
    }
    LED {
    }
    Lidar {
      name "LDS-01"
      translation 0.5 0 0.2
      fieldOfView 6.2832
      maxRange 5.0
      minRange 1.0
      horizontalResolution 200
    }
    DistanceSensor {
      translation 0.042 0.02 0.063
      rotation 0 0 1 0.5236003061004253
      children [
        DEF SENSOR Transform {
          rotation 0 1 0 1.5708
          children [
            Shape {
              appearance PBRAppearance {
                baseColor 1 1 0
                roughness 1
                metalness 0
              }
              geometry Cylinder {
                height 0.004
                radius 0.008
              }
            }
          ]
        }
      ]
      name "ds0"
      lookupTable [
        0 1020 0
        0.05 1020 0
        0.15 0 0
      ]
      numberOfRays 2
      aperture 1
    }
    DistanceSensor {
      translation 0.042 -0.02 0.063
      rotation 0 0 1 -0.5235996938995747
      children [
        USE SENSOR
      ]
      name "ds1"
      lookupTable [
        0 1020 0
        0.05 1020 0
        0.15 0 0
      ]
      numberOfRays 2
      aperture 1
    }
  ]
  boundingObject Transform {
    translation 0 0 0
    children [
      USE BODY
    ]
  }
  physics Physics {
    mass 15.0
  }
  controller "<extern>"
  name "small_robot09"
  translation 3.0 0.0 0.5
	rotation 0 0 1 0.0
}

Robot {
  children [
    HingeJoint {
      jointParameters HingeJointParameters {
        axis 0 1 0
        anchor 0 0 -0.125
      }
      device [
        RotationalMotor {
          name "left wheel motor"
        }
      ]
      endPoint Solid {
        translation 0 0.5 -0.125
        children [
          DEF WHEEL Transform {
            rotation 1 0 0 1.5707996938995747
            children [
              Shape {
                appearance PBRAppearance {
                  baseColor 0 0 0
                  roughness 1
                  metalness 0
                }
                geometry Cylinder {
                  height 0.2
                  radius 0.2
                }
              }
            ]
          }
        ]
        name "left wheel"
        boundingObject USE WHEEL
        physics Physics {
          mass 4
        }
      }
    }
    HingeJoint {
      jointParameters HingeJointParameters {
        axis 0 1 0
        anchor 0 0 -0.125
      }
      device [
        RotationalMotor {
          name "right wheel motor"
        }
      ]
      endPoint Solid {
        translation 0 -0.5 -0.125
        children [
          USE WHEEL
        ]
        name "right wheel"
        boundingObject USE WHEEL
        physics Physics {
          mass 4
        }
      }
    }
    DEF CASTER_JOINT BallJoint {
      jointParameters BallJointParameters {
        anchor -0.4 0 -0.225
      }
      endPoint Solid {
        translation -0.4 0 -0.225
        children [
          Shape {
            appearance PBRAppearance {
            }
            geometry DEF CASTER_SPHERE Sphere {
              radius 0.1
              subdivision 2
            }
          }
        ]
        boundingObject USE CASTER_SPHERE
        physics Physics {
          mass 0.001
        }
      }
    }
    DEF FRONT_CASTER_JOINT BallJoint {
      jointParameters BallJointParameters {
        anchor 0.4 0 -0.225
      }
      endPoint Solid {
        translation 0.4 0 -0.225
        children [
          Shape {
            appearance PBRAppearance {
            }
            geometry DEF CASTER_SPHERE Sphere {
              radius 0.1
              subdivision 2
            }
          }
        ]
        boundingObject USE CASTER_SPHERE
        physics Physics {
          mass 0.001
        }
      }
    }
    Transform {
      translation 0 0 0.0
      children [
        Shape {
          appearance PBRAppearance {
            baseColor 1 0 0
            roughness 1
            metalness 0
          }
          geometry DEF BODY Box {
            size 1.0 1.0 0.55
          }
        }
      ]
    }
    Camera {
        name "cam"
        translation 0.5 0 0.28
        fieldOfView 0.87
        width 324
        height 324
    }
    Gyro {
    }
    InertialUnit {
    }
    Accelerometer {
    }
    GPS {
    }
    LED {
    }
    Lidar {
      name "LDS-01"
      translation 0.5 0 0.2
      fieldOfView 6.2832
      maxRange 5.0
      minRange 1.0
      horizontalResolution 200
    }
    DistanceSensor {
      translation 0.042 0.02 0.063
      rotation 0 0 1 0.5236003061004253
      children [
        DEF SENSOR Transform {
          rotation 0 1 0 1.5708
          children [
            Shape {
              appearance PBRAppearance {
                baseColor 1 1 0
                roughness 1
                metalness 0
              }
              geometry Cylinder {
                height 0.004
                radius 0.008
              }
            }
          ]
        }
      ]
      name "ds0"
      lookupTable [
        0 1020 0
        0.05 1020 0
        0.15 0 0
      ]
      numberOfRays 2
      aperture 1
    }
    DistanceSensor {
      translation 0.042 -0.02 0.063
      rotation 0 0 1 -0.5235996938995747
      children [
        USE SENSOR
      ]
      name "ds1"
      lookupTable [
        0 1020 0
        0.05 1020 0
        0.15 0 0
      ]
      numberOfRays 2
      aperture 1
    }
  ]
  boundingObject Transform {
    translation 0 0 0
    children [
      USE BODY
    ]
  }
  physics Physics {
    mass 15.0
  }
  controller "<extern>"
  name "small_robot10"
  translation 3.0 1.5 0.5
	rotation 0 0 1 0.0
}

Robot {
  children [
    HingeJoint {
      jointParameters HingeJointParameters {
        axis 0 1 0
        anchor 0 0 -0.125
      }
      device [
        RotationalMotor {
          name "left wheel motor"
        }
      ]
      endPoint Solid {
        translation 0 0.5 -0.125
        children [
          DEF WHEEL Transform {
            rotation 1 0 0 1.5707996938995747
            children [
              Shape {
                appearance PBRAppearance {
                  baseColor 0 0 0
                  roughness 1
                  metalness 0
                }
                geometry Cylinder {
                  height 0.2
                  radius 0.2
                }
              }
            ]
          }
        ]
        name "left wheel"
        boundingObject USE WHEEL
        physics Physics {
          mass 4
        }
      }
    }
    HingeJoint {
      jointParameters HingeJointParameters {
        axis 0 1 0
        anchor 0 0 -0.125
      }
      device [
        RotationalMotor {
          name "right wheel motor"
        }
      ]
      endPoint Solid {
        translation 0 -0.5 -0.125
        children [
          USE WHEEL
        ]
        name "right wheel"
        boundingObject USE WHEEL
        physics Physics {
          mass 4
        }
      }
    }
    DEF CASTER_JOINT BallJoint {
      jointParameters BallJointParameters {
        anchor -0.4 0 -0.225
      }
      endPoint Solid {
        translation -0.4 0 -0.225
        children [
          Shape {
            appearance PBRAppearance {
            }
            geometry DEF CASTER_SPHERE Sphere {
              radius 0.1
              subdivision 2
            }
          }
        ]
        boundingObject USE CASTER_SPHERE
        physics Physics {
          mass 0.001
        }
      }
    }
    DEF FRONT_CASTER_JOINT BallJoint {
      jointParameters BallJointParameters {
        anchor 0.4 0 -0.225
      }
      endPoint Solid {
        translation 0.4 0 -0.225
        children [
          Shape {
            appearance PBRAppearance {
            }
            geometry DEF CASTER_SPHERE Sphere {
              radius 0.1
              subdivision 2
            }
          }
        ]
        boundingObject USE CASTER_SPHERE
        physics Physics {
          mass 0.001
        }
      }
    }
    Transform {
      translation 0 0 0.0
      children [
        Shape {
          appearance PBRAppearance {
            baseColor 1 0 0
            roughness 1
            metalness 0
          }
          geometry DEF BODY Box {
            size 1.0 1.0 0.55
          }
        }
      ]
    }
    Camera {
        name "cam"
        translation 0.5 0 0.28
        fieldOfView 0.87
        width 324
        height 324
    }
    Gyro {
    }
    InertialUnit {
    }
    Accelerometer {
    }
    GPS {
    }
    LED {
    }
    Lidar {
      name "LDS-01"
      translation 0.5 0 0.2
      fieldOfView 6.2832
      maxRange 5.0
      minRange 1.0
      horizontalResolution 200
    }
    DistanceSensor {
      translation 0.042 0.02 0.063
      rotation 0 0 1 0.5236003061004253
      children [
        DEF SENSOR Transform {
          rotation 0 1 0 1.5708
          children [
            Shape {
              appearance PBRAppearance {
                baseColor 1 1 0
                roughness 1
                metalness 0
              }
              geometry Cylinder {
                height 0.004
                radius 0.008
              }
            }
          ]
        }
      ]
      name "ds0"
      lookupTable [
        0 1020 0
        0.05 1020 0
        0.15 0 0
      ]
      numberOfRays 2
      aperture 1
    }
    DistanceSensor {
      translation 0.042 -0.02 0.063
      rotation 0 0 1 -0.5235996938995747
      children [
        USE SENSOR
      ]
      name "ds1"
      lookupTable [
        0 1020 0
        0.05 1020 0
        0.15 0 0
      ]
      numberOfRays 2
      aperture 1
    }
  ]
  boundingObject Transform {
    translation 0 0 0
    children [
      USE BODY
    ]
  }
  physics Physics {
    mass 15.0
  }
  controller "<extern>"
  name "small_robot11"
  translation 3.0 3.0 0.5
	rotation 0 0 1 0.0
}

Robot {
  children [
    HingeJoint {
      jointParameters HingeJointParameters {
        axis 0 1 0
        anchor 0 0 -0.125
      }
      device [
        RotationalMotor {
          name "left wheel motor"
        }
      ]
      endPoint Solid {
        translation 0 0.5 -0.125
        children [
          DEF WHEEL Transform {
            rotation 1 0 0 1.5707996938995747
            children [
              Shape {
                appearance PBRAppearance {
                  baseColor 0 0 0
                  roughness 1
                  metalness 0
                }
                geometry Cylinder {
                  height 0.2
                  radius 0.2
                }
              }
            ]
          }
        ]
        name "left wheel"
        boundingObject USE WHEEL
        physics Physics {
          mass 4
        }
      }
    }
    HingeJoint {
      jointParameters HingeJointParameters {
        axis 0 1 0
        anchor 0 0 -0.125
      }
      device [
        RotationalMotor {
          name "right wheel motor"
        }
      ]
      endPoint Solid {
        translation 0 -0.5 -0.125
        children [
          USE WHEEL
        ]
        name "right wheel"
        boundingObject USE WHEEL
        physics Physics {
          mass 4
        }
      }
    }
    DEF CASTER_JOINT BallJoint {
      jointParameters BallJointParameters {
        anchor -0.4 0 -0.225
      }
      endPoint Solid {
        translation -0.4 0 -0.225
        children [
          Shape {
            appearance PBRAppearance {
            }
            geometry DEF CASTER_SPHERE Sphere {
              radius 0.1
              subdivision 2
            }
          }
        ]
        boundingObject USE CASTER_SPHERE
        physics Physics {
          mass 0.001
        }
      }
    }
    DEF FRONT_CASTER_JOINT BallJoint {
      jointParameters BallJointParameters {
        anchor 0.4 0 -0.225
      }
      endPoint Solid {
        translation 0.4 0 -0.225
        children [
          Shape {
            appearance PBRAppearance {
            }
            geometry DEF CASTER_SPHERE Sphere {
              radius 0.1
              subdivision 2
            }
          }
        ]
        boundingObject USE CASTER_SPHERE
        physics Physics {
          mass 0.001
        }
      }
    }
    Transform {
      translation 0 0 0.0
      children [
        Shape {
          appearance PBRAppearance {
            baseColor 1 0 0
            roughness 1
            metalness 0
          }
          geometry DEF BODY Box {
            size 1.0 1.0 0.55
          }
        }
      ]
    }
    Camera {
        name "cam"
        translation 0.5 0 0.28
        fieldOfView 0.87
        width 324
        height 324
    }
    Gyro {
    }
    InertialUnit {
    }
    Accelerometer {
    }
    GPS {
    }
    LED {
    }
    Lidar {
      name "LDS-01"
      translation 0.5 0 0.2
      fieldOfView 6.2832
      maxRange 5.0
      minRange 1.0
      horizontalResolution 200
    }
    DistanceSensor {
      translation 0.042 0.02 0.063
      rotation 0 0 1 0.5236003061004253
      children [
        DEF SENSOR Transform {
          rotation 0 1 0 1.5708
          children [
            Shape {
              appearance PBRAppearance {
                baseColor 1 1 0
                roughness 1
                metalness 0
              }
              geometry Cylinder {
                height 0.004
                radius 0.008
              }
            }
          ]
        }
      ]
      name "ds0"
      lookupTable [
        0 1020 0
        0.05 1020 0
        0.15 0 0
      ]
      numberOfRays 2
      aperture 1
    }
    DistanceSensor {
      translation 0.042 -0.02 0.063
      rotation 0 0 1 -0.5235996938995747
      children [
        USE SENSOR
      ]
      name "ds1"
      lookupTable [
        0 1020 0
        0.05 1020 0
        0.15 0 0
      ]
      numberOfRays 2
      aperture 1
    }
  ]
  boundingObject Transform {
    translation 0 0 0
    children [
      USE BODY
    ]
  }
  physics Physics {
    mass 15.0
  }
  controller "<extern>"
  name "small_robot12"
  translation 1.5 3.0 0.5
	rotation 0 0 1 0.0
}

Robot {
  children [
    HingeJoint {
      jointParameters HingeJointParameters {
        axis 0 1 0
        anchor 0 0 -0.125
      }
      device [
        RotationalMotor {
          name "left wheel motor"
        }
      ]
      endPoint Solid {
        translation 0 0.5 -0.125
        children [
          DEF WHEEL Transform {
            rotation 1 0 0 1.5707996938995747
            children [
              Shape {
                appearance PBRAppearance {
                  baseColor 0 0 0
                  roughness 1
                  metalness 0
                }
                geometry Cylinder {
                  height 0.2
                  radius 0.2
                }
              }
            ]
          }
        ]
        name "left wheel"
        boundingObject USE WHEEL
        physics Physics {
          mass 4
        }
      }
    }
    HingeJoint {
      jointParameters HingeJointParameters {
        axis 0 1 0
        anchor 0 0 -0.125
      }
      device [
        RotationalMotor {
          name "right wheel motor"
        }
      ]
      endPoint Solid {
        translation 0 -0.5 -0.125
        children [
          USE WHEEL
        ]
        name "right wheel"
        boundingObject USE WHEEL
        physics Physics {
          mass 4
        }
      }
    }
    DEF CASTER_JOINT BallJoint {
      jointParameters BallJointParameters {
        anchor -0.4 0 -0.225
      }
      endPoint Solid {
        translation -0.4 0 -0.225
        children [
          Shape {
            appearance PBRAppearance {
            }
            geometry DEF CASTER_SPHERE Sphere {
              radius 0.1
              subdivision 2
            }
          }
        ]
        boundingObject USE CASTER_SPHERE
        physics Physics {
          mass 0.001
        }
      }
    }
    DEF FRONT_CASTER_JOINT BallJoint {
      jointParameters BallJointParameters {
        anchor 0.4 0 -0.225
      }
      endPoint Solid {
        translation 0.4 0 -0.225
        children [
          Shape {
            appearance PBRAppearance {
            }
            geometry DEF CASTER_SPHERE Sphere {
              radius 0.1
              subdivision 2
            }
          }
        ]
        boundingObject USE CASTER_SPHERE
        physics Physics {
          mass 0.001
        }
      }
    }
    Transform {
      translation 0 0 0.0
      children [
        Shape {
          appearance PBRAppearance {
            baseColor 1 0 0
            roughness 1
            metalness 0
          }
          geometry DEF BODY Box {
            size 1.0 1.0 0.55
          }
        }
      ]
    }
    Camera {
        name "cam"
        translation 0.5 0 0.28
        fieldOfView 0.87
        width 324
        height 324
    }
    Gyro {
    }
    InertialUnit {
    }
    Accelerometer {
    }
    GPS {
    }
    LED {
    }
    Lidar {
      name "LDS-01"
      translation 0.5 0 0.2
      fieldOfView 6.2832
      maxRange 5.0
      minRange 1.0
      horizontalResolution 200
    }
    DistanceSensor {
      translation 0.042 0.02 0.063
      rotation 0 0 1 0.5236003061004253
      children [
        DEF SENSOR Transform {
          rotation 0 1 0 1.5708
          children [
            Shape {
              appearance PBRAppearance {
                baseColor 1 1 0
                roughness 1
                metalness 0
              }
              geometry Cylinder {
                height 0.004
                radius 0.008
              }
            }
          ]
        }
      ]
      name "ds0"
      lookupTable [
        0 1020 0
        0.05 1020 0
        0.15 0 0
      ]
      numberOfRays 2
      aperture 1
    }
    DistanceSensor {
      translation 0.042 -0.02 0.063
      rotation 0 0 1 -0.5235996938995747
      children [
        USE SENSOR
      ]
      name "ds1"
      lookupTable [
        0 1020 0
        0.05 1020 0
        0.15 0 0
      ]
      numberOfRays 2
      aperture 1
    }
  ]
  boundingObject Transform {
    translation 0 0 0
    children [
      USE BODY
    ]
  }
  physics Physics {
    mass 15.0
  }
  controller "<extern>"
  name "small_robot13"
  translation 0.0 3.0 0.5
	rotation 0 0 1 0.0
}

Robot {
  children [
    HingeJoint {
      jointParameters HingeJointParameters {
        axis 0 1 0
        anchor 0 0 -0.125
      }
      device [
        RotationalMotor {
          name "left wheel motor"
        }
      ]
      endPoint Solid {
        translation 0 0.5 -0.125
        children [
          DEF WHEEL Transform {
            rotation 1 0 0 1.5707996938995747
            children [
              Shape {
                appearance PBRAppearance {
                  baseColor 0 0 0
                  roughness 1
                  metalness 0
                }
                geometry Cylinder {
                  height 0.2
                  radius 0.2
                }
              }
            ]
          }
        ]
        name "left wheel"
        boundingObject USE WHEEL
        physics Physics {
          mass 4
        }
      }
    }
    HingeJoint {
      jointParameters HingeJointParameters {
        axis 0 1 0
        anchor 0 0 -0.125
      }
      device [
        RotationalMotor {
          name "right wheel motor"
        }
      ]
      endPoint Solid {
        translation 0 -0.5 -0.125
        children [
          USE WHEEL
        ]
        name "right wheel"
        boundingObject USE WHEEL
        physics Physics {
          mass 4
        }
      }
    }
    DEF CASTER_JOINT BallJoint {
      jointParameters BallJointParameters {
        anchor -0.4 0 -0.225
      }
      endPoint Solid {
        translation -0.4 0 -0.225
        children [
          Shape {
            appearance PBRAppearance {
            }
            geometry DEF CASTER_SPHERE Sphere {
              radius 0.1
              subdivision 2
            }
          }
        ]
        boundingObject USE CASTER_SPHERE
        physics Physics {
          mass 0.001
        }
      }
    }
    DEF FRONT_CASTER_JOINT BallJoint {
      jointParameters BallJointParameters {
        anchor 0.4 0 -0.225
      }
      endPoint Solid {
        translation 0.4 0 -0.225
        children [
          Shape {
            appearance PBRAppearance {
            }
            geometry DEF CASTER_SPHERE Sphere {
              radius 0.1
              subdivision 2
            }
          }
        ]
        boundingObject USE CASTER_SPHERE
        physics Physics {
          mass 0.001
        }
      }
    }
    Transform {
      translation 0 0 0.0
      children [
        Shape {
          appearance PBRAppearance {
            baseColor 1 0 0
            roughness 1
            metalness 0
          }
          geometry DEF BODY Box {
            size 1.0 1.0 0.55
          }
        }
      ]
    }
    Camera {
        name "cam"
        translation 0.5 0 0.28
        fieldOfView 0.87
        width 324
        height 324
    }
    Gyro {
    }
    InertialUnit {
    }
    Accelerometer {
    }
    GPS {
    }
    LED {
    }
    Lidar {
      name "LDS-01"
      translation 0.5 0 0.2
      fieldOfView 6.2832
      maxRange 5.0
      minRange 1.0
      horizontalResolution 200
    }
    DistanceSensor {
      translation 0.042 0.02 0.063
      rotation 0 0 1 0.5236003061004253
      children [
        DEF SENSOR Transform {
          rotation 0 1 0 1.5708
          children [
            Shape {
              appearance PBRAppearance {
                baseColor 1 1 0
                roughness 1
                metalness 0
              }
              geometry Cylinder {
                height 0.004
                radius 0.008
              }
            }
          ]
        }
      ]
      name "ds0"
      lookupTable [
        0 1020 0
        0.05 1020 0
        0.15 0 0
      ]
      numberOfRays 2
      aperture 1
    }
    DistanceSensor {
      translation 0.042 -0.02 0.063
      rotation 0 0 1 -0.5235996938995747
      children [
        USE SENSOR
      ]
      name "ds1"
      lookupTable [
        0 1020 0
        0.05 1020 0
        0.15 0 0
      ]
      numberOfRays 2
      aperture 1
    }
  ]
  boundingObject Transform {
    translation 0 0 0
    children [
      USE BODY
    ]
  }
  physics Physics {
    mass 15.0
  }
  controller "<extern>"
  name "small_robot14"
  translation -1.5 3.0 0.5
	rotation 0 0 1 0.0
}

Robot {
  children [
    HingeJoint {
      jointParameters HingeJointParameters {
        axis 0 1 0
        anchor 0 0 -0.125
      }
      device [
        RotationalMotor {
          name "left wheel motor"
        }
      ]
      endPoint Solid {
        translation 0 0.5 -0.125
        children [
          DEF WHEEL Transform {
            rotation 1 0 0 1.5707996938995747
            children [
              Shape {
                appearance PBRAppearance {
                  baseColor 0 0 0
                  roughness 1
                  metalness 0
                }
                geometry Cylinder {
                  height 0.2
                  radius 0.2
                }
              }
            ]
          }
        ]
        name "left wheel"
        boundingObject USE WHEEL
        physics Physics {
          mass 4
        }
      }
    }
    HingeJoint {
      jointParameters HingeJointParameters {
        axis 0 1 0
        anchor 0 0 -0.125
      }
      device [
        RotationalMotor {
          name "right wheel motor"
        }
      ]
      endPoint Solid {
        translation 0 -0.5 -0.125
        children [
          USE WHEEL
        ]
        name "right wheel"
        boundingObject USE WHEEL
        physics Physics {
          mass 4
        }
      }
    }
    DEF CASTER_JOINT BallJoint {
      jointParameters BallJointParameters {
        anchor -0.4 0 -0.225
      }
      endPoint Solid {
        translation -0.4 0 -0.225
        children [
          Shape {
            appearance PBRAppearance {
            }
            geometry DEF CASTER_SPHERE Sphere {
              radius 0.1
              subdivision 2
            }
          }
        ]
        boundingObject USE CASTER_SPHERE
        physics Physics {
          mass 0.001
        }
      }
    }
    DEF FRONT_CASTER_JOINT BallJoint {
      jointParameters BallJointParameters {
        anchor 0.4 0 -0.225
      }
      endPoint Solid {
        translation 0.4 0 -0.225
        children [
          Shape {
            appearance PBRAppearance {
            }
            geometry DEF CASTER_SPHERE Sphere {
              radius 0.1
              subdivision 2
            }
          }
        ]
        boundingObject USE CASTER_SPHERE
        physics Physics {
          mass 0.001
        }
      }
    }
    Transform {
      translation 0 0 0.0
      children [
        Shape {
          appearance PBRAppearance {
            baseColor 1 0 0
            roughness 1
            metalness 0
          }
          geometry DEF BODY Box {
            size 1.0 1.0 0.55
          }
        }
      ]
    }
    Camera {
        name "cam"
        translation 0.5 0 0.28
        fieldOfView 0.87
        width 324
        height 324
    }
    Gyro {
    }
    InertialUnit {
    }
    Accelerometer {
    }
    GPS {
    }
    LED {
    }
    Lidar {
      name "LDS-01"
      translation 0.5 0 0.2
      fieldOfView 6.2832
      maxRange 5.0
      minRange 1.0
      horizontalResolution 200
    }
    DistanceSensor {
      translation 0.042 0.02 0.063
      rotation 0 0 1 0.5236003061004253
      children [
        DEF SENSOR Transform {
          rotation 0 1 0 1.5708
          children [
            Shape {
              appearance PBRAppearance {
                baseColor 1 1 0
                roughness 1
                metalness 0
              }
              geometry Cylinder {
                height 0.004
                radius 0.008
              }
            }
          ]
        }
      ]
      name "ds0"
      lookupTable [
        0 1020 0
        0.05 1020 0
        0.15 0 0
      ]
      numberOfRays 2
      aperture 1
    }
    DistanceSensor {
      translation 0.042 -0.02 0.063
      rotation 0 0 1 -0.5235996938995747
      children [
        USE SENSOR
      ]
      name "ds1"
      lookupTable [
        0 1020 0
        0.05 1020 0
        0.15 0 0
      ]
      numberOfRays 2
      aperture 1
    }
  ]
  boundingObject Transform {
    translation 0 0 0
    children [
      USE BODY
    ]
  }
  physics Physics {
    mass 15.0
  }
  controller "<extern>"
  name "small_robot15"
  translation -3.0 3.0 0.5
	rotation 0 0 1 0.0
}

Robot {
  children [
    HingeJoint {
      jointParameters HingeJointParameters {
        axis 0 1 0
        anchor 0 0 -0.125
      }
      device [
        RotationalMotor {
          name "left wheel motor"
        }
      ]
      endPoint Solid {
        translation 0 0.5 -0.125
        children [
          DEF WHEEL Transform {
            rotation 1 0 0 1.5707996938995747
            children [
              Shape {
                appearance PBRAppearance {
                  baseColor 0 0 0
                  roughness 1
                  metalness 0
                }
                geometry Cylinder {
                  height 0.2
                  radius 0.2
                }
              }
            ]
          }
        ]
        name "left wheel"
        boundingObject USE WHEEL
        physics Physics {
          mass 4
        }
      }
    }
    HingeJoint {
      jointParameters HingeJointParameters {
        axis 0 1 0
        anchor 0 0 -0.125
      }
      device [
        RotationalMotor {
          name "right wheel motor"
        }
      ]
      endPoint Solid {
        translation 0 -0.5 -0.125
        children [
          USE WHEEL
        ]
        name "right wheel"
        boundingObject USE WHEEL
        physics Physics {
          mass 4
        }
      }
    }
    DEF CASTER_JOINT BallJoint {
      jointParameters BallJointParameters {
        anchor -0.4 0 -0.225
      }
      endPoint Solid {
        translation -0.4 0 -0.225
        children [
          Shape {
            appearance PBRAppearance {
            }
            geometry DEF CASTER_SPHERE Sphere {
              radius 0.1
              subdivision 2
            }
          }
        ]
        boundingObject USE CASTER_SPHERE
        physics Physics {
          mass 0.001
        }
      }
    }
    DEF FRONT_CASTER_JOINT BallJoint {
      jointParameters BallJointParameters {
        anchor 0.4 0 -0.225
      }
      endPoint Solid {
        translation 0.4 0 -0.225
        children [
          Shape {
            appearance PBRAppearance {
            }
            geometry DEF CASTER_SPHERE Sphere {
              radius 0.1
              subdivision 2
            }
          }
        ]
        boundingObject USE CASTER_SPHERE
        physics Physics {
          mass 0.001
        }
      }
    }
    Transform {
      translation 0 0 0.0
      children [
        Shape {
          appearance PBRAppearance {
            baseColor 1 0 0
            roughness 1
            metalness 0
          }
          geometry DEF BODY Box {
            size 1.0 1.0 0.55
          }
        }
      ]
    }
    Camera {
        name "cam"
        translation 0.5 0 0.28
        fieldOfView 0.87
        width 324
        height 324
    }
    Gyro {
    }
    InertialUnit {
    }
    Accelerometer {
    }
    GPS {
    }
    LED {
    }
    Lidar {
      name "LDS-01"
      translation 0.5 0 0.2
      fieldOfView 6.2832
      maxRange 5.0
      minRange 1.0
      horizontalResolution 200
    }
    DistanceSensor {
      translation 0.042 0.02 0.063
      rotation 0 0 1 0.5236003061004253
      children [
        DEF SENSOR Transform {
          rotation 0 1 0 1.5708
          children [
            Shape {
              appearance PBRAppearance {
                baseColor 1 1 0
                roughness 1
                metalness 0
              }
              geometry Cylinder {
                height 0.004
                radius 0.008
              }
            }
          ]
        }
      ]
      name "ds0"
      lookupTable [
        0 1020 0
        0.05 1020 0
        0.15 0 0
      ]
      numberOfRays 2
      aperture 1
    }
    DistanceSensor {
      translation 0.042 -0.02 0.063
      rotation 0 0 1 -0.5235996938995747
      children [
        USE SENSOR
      ]
      name "ds1"
      lookupTable [
        0 1020 0
        0.05 1020 0
        0.15 0 0
      ]
      numberOfRays 2
      aperture 1
    }
  ]
  boundingObject Transform {
    translation 0 0 0
    children [
      USE BODY
    ]
  }
  physics Physics {
    mass 15.0
  }
  controller "<extern>"
  name "small_robot16"
  translation -3.0 1.5 0.5
	rotation 0 0 1 0.0
}

Robot {
  children [
    HingeJoint {
      jointParameters HingeJointParameters {
        axis 0 1 0
        anchor 0 0 -0.125
      }
      device [
        RotationalMotor {
          name "left wheel motor"
        }
      ]
      endPoint Solid {
        translation 0 0.5 -0.125
        children [
          DEF WHEEL Transform {
            rotation 1 0 0 1.5707996938995747
            children [
              Shape {
                appearance PBRAppearance {
                  baseColor 0 0 0
                  roughness 1
                  metalness 0
                }
                geometry Cylinder {
                  height 0.2
                  radius 0.2
                }
              }
            ]
          }
        ]
        name "left wheel"
        boundingObject USE WHEEL
        physics Physics {
          mass 4
        }
      }
    }
    HingeJoint {
      jointParameters HingeJointParameters {
        axis 0 1 0
        anchor 0 0 -0.125
      }
      device [
        RotationalMotor {
          name "right wheel motor"
        }
      ]
      endPoint Solid {
        translation 0 -0.5 -0.125
        children [
          USE WHEEL
        ]
        name "right wheel"
        boundingObject USE WHEEL
        physics Physics {
          mass 4
        }
      }
    }
    DEF CASTER_JOINT BallJoint {
      jointParameters BallJointParameters {
        anchor -0.4 0 -0.225
      }
      endPoint Solid {
        translation -0.4 0 -0.225
        children [
          Shape {
            appearance PBRAppearance {
            }
            geometry DEF CASTER_SPHERE Sphere {
              radius 0.1
              subdivision 2
            }
          }
        ]
        boundingObject USE CASTER_SPHERE
        physics Physics {
          mass 0.001
        }
      }
    }
    DEF FRONT_CASTER_JOINT BallJoint {
      jointParameters BallJointParameters {
        anchor 0.4 0 -0.225
      }
      endPoint Solid {
        translation 0.4 0 -0.225
        children [
          Shape {
            appearance PBRAppearance {
            }
            geometry DEF CASTER_SPHERE Sphere {
              radius 0.1
              subdivision 2
            }
          }
        ]
        boundingObject USE CASTER_SPHERE
        physics Physics {
          mass 0.001
        }
      }
    }
    Transform {
      translation 0 0 0.0
      children [
        Shape {
          appearance PBRAppearance {
            baseColor 1 0 0
            roughness 1
            metalness 0
          }
          geometry DEF BODY Box {
            size 1.0 1.0 0.55
          }
        }
      ]
    }
    Camera {
        name "cam"
        translation 0.5 0 0.28
        fieldOfView 0.87
        width 324
        height 324
    }
    Gyro {
    }
    InertialUnit {
    }
    Accelerometer {
    }
    GPS {
    }
    LED {
    }
    Lidar {
      name "LDS-01"
      translation 0.5 0 0.2
      fieldOfView 6.2832
      maxRange 5.0
      minRange 1.0
      horizontalResolution 200
    }
    DistanceSensor {
      translation 0.042 0.02 0.063
      rotation 0 0 1 0.5236003061004253
      children [
        DEF SENSOR Transform {
          rotation 0 1 0 1.5708
          children [
            Shape {
              appearance PBRAppearance {
                baseColor 1 1 0
                roughness 1
                metalness 0
              }
              geometry Cylinder {
                height 0.004
                radius 0.008
              }
            }
          ]
        }
      ]
      name "ds0"
      lookupTable [
        0 1020 0
        0.05 1020 0
        0.15 0 0
      ]
      numberOfRays 2
      aperture 1
    }
    DistanceSensor {
      translation 0.042 -0.02 0.063
      rotation 0 0 1 -0.5235996938995747
      children [
        USE SENSOR
      ]
      name "ds1"
      lookupTable [
        0 1020 0
        0.05 1020 0
        0.15 0 0
      ]
      numberOfRays 2
      aperture 1
    }
  ]
  boundingObject Transform {
    translation 0 0 0
    children [
      USE BODY
    ]
  }
  physics Physics {
    mass 15.0
  }
  controller "<extern>"
  name "small_robot17"
  translation -3.0 0.0 0.5
	rotation 0 0 1 0.0
}

Robot {
  children [
    HingeJoint {
      jointParameters HingeJointParameters {
        axis 0 1 0
        anchor 0 0 -0.125
      }
      device [
        RotationalMotor {
          name "left wheel motor"
        }
      ]
      endPoint Solid {
        translation 0 0.5 -0.125
        children [
          DEF WHEEL Transform {
            rotation 1 0 0 1.5707996938995747
            children [
              Shape {
                appearance PBRAppearance {
                  baseColor 0 0 0
                  roughness 1
                  metalness 0
                }
                geometry Cylinder {
                  height 0.2
                  radius 0.2
                }
              }
            ]
          }
        ]
        name "left wheel"
        boundingObject USE WHEEL
        physics Physics {
          mass 4
        }
      }
    }
    HingeJoint {
      jointParameters HingeJointParameters {
        axis 0 1 0
        anchor 0 0 -0.125
      }
      device [
        RotationalMotor {
          name "right wheel motor"
        }
      ]
      endPoint Solid {
        translation 0 -0.5 -0.125
        children [
          USE WHEEL
        ]
        name "right wheel"
        boundingObject USE WHEEL
        physics Physics {
          mass 4
        }
      }
    }
    DEF CASTER_JOINT BallJoint {
      jointParameters BallJointParameters {
        anchor -0.4 0 -0.225
      }
      endPoint Solid {
        translation -0.4 0 -0.225
        children [
          Shape {
            appearance PBRAppearance {
            }
            geometry DEF CASTER_SPHERE Sphere {
              radius 0.1
              subdivision 2
            }
          }
        ]
        boundingObject USE CASTER_SPHERE
        physics Physics {
          mass 0.001
        }
      }
    }
    DEF FRONT_CASTER_JOINT BallJoint {
      jointParameters BallJointParameters {
        anchor 0.4 0 -0.225
      }
      endPoint Solid {
        translation 0.4 0 -0.225
        children [
          Shape {
            appearance PBRAppearance {
            }
            geometry DEF CASTER_SPHERE Sphere {
              radius 0.1
              subdivision 2
            }
          }
        ]
        boundingObject USE CASTER_SPHERE
        physics Physics {
          mass 0.001
        }
      }
    }
    Transform {
      translation 0 0 0.0
      children [
        Shape {
          appearance PBRAppearance {
            baseColor 1 0 0
            roughness 1
            metalness 0
          }
          geometry DEF BODY Box {
            size 1.0 1.0 0.55
          }
        }
      ]
    }
    Camera {
        name "cam"
        translation 0.5 0 0.28
        fieldOfView 0.87
        width 324
        height 324
    }
    Gyro {
    }
    InertialUnit {
    }
    Accelerometer {
    }
    GPS {
    }
    LED {
    }
    Lidar {
      name "LDS-01"
      translation 0.5 0 0.2
      fieldOfView 6.2832
      maxRange 5.0
      minRange 1.0
      horizontalResolution 200
    }
    DistanceSensor {
      translation 0.042 0.02 0.063
      rotation 0 0 1 0.5236003061004253
      children [
        DEF SENSOR Transform {
          rotation 0 1 0 1.5708
          children [
            Shape {
              appearance PBRAppearance {
                baseColor 1 1 0
                roughness 1
                metalness 0
              }
              geometry Cylinder {
                height 0.004
                radius 0.008
              }
            }
          ]
        }
      ]
      name "ds0"
      lookupTable [
        0 1020 0
        0.05 1020 0
        0.15 0 0
      ]
      numberOfRays 2
      aperture 1
    }
    DistanceSensor {
      translation 0.042 -0.02 0.063
      rotation 0 0 1 -0.5235996938995747
      children [
        USE SENSOR
      ]
      name "ds1"
      lookupTable [
        0 1020 0
        0.05 1020 0
        0.15 0 0
      ]
      numberOfRays 2
      aperture 1
    }
  ]
  boundingObject Transform {
    translation 0 0 0
    children [
      USE BODY
    ]
  }
  physics Physics {
    mass 15.0
  }
  controller "<extern>"
  name "small_robot18"
  translation -3.0 -1.5 0.5
	rotation 0 0 1 0.0
}

Robot {
  children [
    HingeJoint {
      jointParameters HingeJointParameters {
        axis 0 1 0
        anchor 0 0 -0.125
      }
      device [
        RotationalMotor {
          name "left wheel motor"
        }
      ]
      endPoint Solid {
        translation 0 0.5 -0.125
        children [
          DEF WHEEL Transform {
            rotation 1 0 0 1.5707996938995747
            children [
              Shape {
                appearance PBRAppearance {
                  baseColor 0 0 0
                  roughness 1
                  metalness 0
                }
                geometry Cylinder {
                  height 0.2
                  radius 0.2
                }
              }
            ]
          }
        ]
        name "left wheel"
        boundingObject USE WHEEL
        physics Physics {
          mass 4
        }
      }
    }
    HingeJoint {
      jointParameters HingeJointParameters {
        axis 0 1 0
        anchor 0 0 -0.125
      }
      device [
        RotationalMotor {
          name "right wheel motor"
        }
      ]
      endPoint Solid {
        translation 0 -0.5 -0.125
        children [
          USE WHEEL
        ]
        name "right wheel"
        boundingObject USE WHEEL
        physics Physics {
          mass 4
        }
      }
    }
    DEF CASTER_JOINT BallJoint {
      jointParameters BallJointParameters {
        anchor -0.4 0 -0.225
      }
      endPoint Solid {
        translation -0.4 0 -0.225
        children [
          Shape {
            appearance PBRAppearance {
            }
            geometry DEF CASTER_SPHERE Sphere {
              radius 0.1
              subdivision 2
            }
          }
        ]
        boundingObject USE CASTER_SPHERE
        physics Physics {
          mass 0.001
        }
      }
    }
    DEF FRONT_CASTER_JOINT BallJoint {
      jointParameters BallJointParameters {
        anchor 0.4 0 -0.225
      }
      endPoint Solid {
        translation 0.4 0 -0.225
        children [
          Shape {
            appearance PBRAppearance {
            }
            geometry DEF CASTER_SPHERE Sphere {
              radius 0.1
              subdivision 2
            }
          }
        ]
        boundingObject USE CASTER_SPHERE
        physics Physics {
          mass 0.001
        }
      }
    }
    Transform {
      translation 0 0 0.0
      children [
        Shape {
          appearance PBRAppearance {
            baseColor 1 0 0
            roughness 1
            metalness 0
          }
          geometry DEF BODY Box {
            size 1.0 1.0 0.55
          }
        }
      ]
    }
    Camera {
        name "cam"
        translation 0.5 0 0.28
        fieldOfView 0.87
        width 324
        height 324
    }
    Gyro {
    }
    InertialUnit {
    }
    Accelerometer {
    }
    GPS {
    }
    LED {
    }
    Lidar {
      name "LDS-01"
      translation 0.5 0 0.2
      fieldOfView 6.2832
      maxRange 5.0
      minRange 1.0
      horizontalResolution 200
    }
    DistanceSensor {
      translation 0.042 0.02 0.063
      rotation 0 0 1 0.5236003061004253
      children [
        DEF SENSOR Transform {
          rotation 0 1 0 1.5708
          children [
            Shape {
              appearance PBRAppearance {
                baseColor 1 1 0
                roughness 1
                metalness 0
              }
              geometry Cylinder {
                height 0.004
                radius 0.008
              }
            }
          ]
        }
      ]
      name "ds0"
      lookupTable [
        0 1020 0
        0.05 1020 0
        0.15 0 0
      ]
      numberOfRays 2
      aperture 1
    }
    DistanceSensor {
      translation 0.042 -0.02 0.063
      rotation 0 0 1 -0.5235996938995747
      children [
        USE SENSOR
      ]
      name "ds1"
      lookupTable [
        0 1020 0
        0.05 1020 0
        0.15 0 0
      ]
      numberOfRays 2
      aperture 1
    }
  ]
  boundingObject Transform {
    translation 0 0 0
    children [
      USE BODY
    ]
  }
  physics Physics {
    mass 15.0
  }
  controller "<extern>"
  name "small_robot19"
  translation -3.0 -3.0 0.5
	rotation 0 0 1 0.0
}